Workbook

Sheet MASTER DATA
A1: Material | B1: Material Description | C1: Storage Location | D1: Batch | E1: UPP | F1: VOLUME
A2: 550062461 | B2: Advan4TAX710W40SNMA2_12*0.8L_A04W | C2: WHS1 | D2: UT | E2: 48 | F2: 9.6
A3: 550070612 | B3: HlxHX610W40SP_12*1L_A04W | C3: WHS1 | D3: UT | E3: 44 | F3: 12
A4: 550070614 | B4: HlxHX610W40SP_4*4L_A04W | C4: WHS1 | D4: UT | E4: 36 | F4: 16
A5: 550053782 | B5: RimR5E10W40CI4228.3_4*4L_A734 | C5: WHS1 | D5: UT | E5: 36 | F5: 16
A6: 550058593 | B6: Adv4TAX515W40SLMA2_12*0.8L_A04W | C6: WHS1 | D6: UT | E6: 48 | F6: 9.6
A7: 550044709 | B7: Adv4TAX5Sc10W30SLMB_12*0.8L_A04W | C7: WHS1 | D7: UT | E7: 48 | F7: 9.6
A8: 550048593 | B8: Adv4TAX5Sc20W40MB_12*0.8L_A04W | C8: WHS1 | D8: UT | E8: 48 | F8: 9.6
A9: 550050072 | B9: RimLD4Extra15W40CI4_3*5L_A04W | C9: WHS1 | D9: UT | E9: 36 | F9: 15
A10: 550062455 | B10: AdvaPowerV15W50SNMA2_12*1L_A04W | C10: WHS1 | D10: UT | E10: 44 | F10: 12
A11: 550062464 | B11: Adv4TAX7Sc10W30SNMB_12*0.8L_A04W | C11: WHS1 | D11: UT | E11: 48 | F11: 9.6
A12: 550024959 | B12: Refrig S2 FR-A 68_1*209L_A227 | C12: WHS1 | D12: UT | E12: 4 | F12: 209
A13: 550056225 | B13: IAGO DEO 15W-40 CI4_12*1L_A423 | C13: WHS1 | D13: UT | E13: 44 | F13: 12
... A157: 550025044 | B157: Spirax S2 A 85W-140_1*209L_A227 | C157: WHS1 | D157: UT | E157: 4 | F157: 209
A158: 550025702 | B158: Refrig S4 FR-V 68_1*20L_A1P5 | C158: WHS1 | D158: UT | E158: 24 | F158: 20 | G158: pail
A159: 550027031 | B159: Gadus S2 V220 2_1*18kg_A227 | C159: WHS1 | D159: UT | E159: 24 | F159: 18 | G159: pail
A160: 550027265 | B160: Corena S4 P 100_1*20L_A1P5 | C160: WHS1 | D160: UT | E160: 24 | F160: 20 | G160: pail
A161: 550075025 | B161: ShellCoolExtraRTU_12*0.65L_A410 | C161: WHS1 | D161: UT | E161: 48 | F161: 7.8 | G161: CAR
A162: 550045086 | B162: Tellus S2 MX 100_1*209L_A227 | C162: WHS1 | D162: UT | E162: 4 | F162: 209
A163: 550047464 | B163: Omala S4 GXV 680_1*209L_A227 | C163: WHS1 | D163: UT | E163: 4 | F163: 209
A164: 550025675 | B164: Gadus S2 V220AC 2_1*180kg_A227 | C164: WHS1 | D164: UT | E164: 4 | F164: 180 | G164: EA
A165: 550032917 | B165: Turbo T 46_1*209L_A227 | C165: WHS1 | D165: UT | E165: 4 | F165: 209 | G165: EA
A166: 550025358 | B166: Spirax S3 G 80W_12*1L_A04W | C166: WHS1 | D166: UT | E166: 44 | F166: 12
A167: 550072297 | B167: HelixPowerV0W40SP_4*4L_A04W | C167: WHS1 | D167: UT | E167: 36 | F167: 16
A168: 550062631 | B168: KawaSemiSyn10W40SLMA_12*1L_A734 | C168: WHS1 | D168: UT | E168: 44 | F168: 12
A169: 550062285 | B169: Gadus S3 V460DM 2_1*770kg_A227 | C169: WHS1 | D169: UT | E169: 1 | F169: 770
A170: 550075616 | B170: SHELLCOOLELCHDRTU Y_1*205L_A04W | C170: WHS1 | D170: UT | E170: 4 | F170: 205
A171: 550044623 | B171: Rimula R2 10W (CF)_1*209L_A227 | C171: WHS1 | D171: UT | E171: 4 | F171: 209
A172: 550024918 | B172: Spirax S4 CX 10W_1*209L_A227 | C172: WHS1 | D172: UT | E172: 4 | F172: 209
A173: 550077498 | B173: HlxUltSQ0W20dexos_12*1L_A04W | C173: WHS1 | D173: UT | E173: 44 | F173: 12
A174: 550077927 | B174: HlxHX610W30SP_4*4L_A04W | C174: WHS1 | D174: UT | E174: 36 | F174: 16
A175: 550041490 | B175: Omala S2 GX 150_1*209L_A227 | C175: WHS1 | D175: UT | E175: 4 | F175: 209
A176: 550027051 | B176: Gadus S2 V100 2_1*180kg_A227 | C176: WHS1 | D176: UT | E176: 4 | F176: 180
A177: 550053106 | B177: HelixAST0W20SNGF5_12*1L_A04W | C177: WHS1 | D177: UT | E177: 44 | F177: 12
... A182: 550076426 | B182: MIDEL 7131_1*1000L_A1P5 | C182: WHS1 | D182: UT | E182: 1 | F182: 1000
A183: 550045081 | B183: Tellus S2 VX 100_1*209L_A227 | E183: 4 | F183: 209
A184: 550047463 | B184: Omala S4 GXV 460 1*209L | C184: WHS1 | D184: UT | E184: 4 | F184: 209
A185: 550053104 | B185: HelixAst5W30_SP_12*1L_A04W | C185: WHS1 | D185: UT | E185: 44 | F185: 12
A186: 550077926 | B186: HlxHX610W30SP_12*1L_A04W | C186: WHS1 | D186: UT | E186: 44 | F186: 12
A187: 550069979 | B187: HlxUltSP5W30SP_12*1L_A04W | C187: CAR | E187: 44 | F187: 12
...

Sheet data level A
A2: Remain Qty | B2: (Multiple Items)
A3: sss | B3: A
A5: Sum of Remain Qty
A6: Item | B6: Description | C6: Lokasi | D6: Total
A7: 550024918 | B7: Spirax S4 CX 10W_1*209L_A227 | C7: CD40A02 | D7: 2
A8: 550024921 | B8: Spirax S2 G 90_1*209L_A227 | C8: CB03A01 | D8: 3
B9: Spirax S2 G 90_1*209L_A227 | C9: CD10A01 | D9: 4
A10: 550024929 | B10: Spirax S2 A 90_1*209L_A227 | C10: CB12A02 | D10: 2
B11: Spirax S2 A 90_1*209L_A227 | C11: CB39A01 | D11: 2
A12: 550024953 | B12: Corena S4 R 68_1*209L_A227 | C12: CB08A01 | D12: 2
B13: Corena S4 R 68_1*209L_A227 | C13: CD25A02 | D13: 3
A14: 550024992 | B14: Corena S2 P 100_1*209L_A227 | C14: CB08A02 | D14: 1
A15: 550025043 | B15: Spirax S2 A 80W-90_1*209L_A227 | C15: CD21A02 | D15: 2
A16: 550025044 | B16: Spirax S2 A 85W-140_1*209L_A227 | C16: CB24A01 | D16: 1
B17: Spirax S2 A 85W-140_1*209L_A227 | C17: CD33A02 | D17: 1
B18: Spirax S2 A 85W-140_1*209L_A227 | C18: CE18A02 | D18: 1
A19: 550025058 | B19: Spirax S2 G 90_4*4L_A04W | C19: CD07A02 | D19: 6
A20: 550025358 | B20: Spirax S3 G 80W_12*1L_A04W | C20: CD01A02 | D20: 7
A21: 550027044 | B21: Gadus S3 V220C 3_1*18kg_A227 | C21: CB35A01 | D21: 5
A22: 550027259 | B22: Gadus S2 V220 2_1*770kg_A227 | C22: CD22A01 | D22: 1
B23: Gadus S2 V220 2_1*770kg_A227 | C23: CD22A02 | D23: 1
B24: Gadus S2 V220 2_1*770kg_A227 | C24: CD23A01 | D24: 1
B25: Gadus S2 V220 2_1*770kg_A227 | C25: CD23A02 | D25: 1
B26: Gadus S2 V220 2_1*770kg_A227 | C26: CD39A01 | D26: 1
B27: Gadus S2 V220 2_1*770kg_A227 | C27: CE27A02 | D27: 1
B28: Gadus S2 V220 2_1*770kg_A227 | C28: CE28A02 | D28: 1
B29: Gadus S2 V220 2_1*770kg_A227 | C29: CE30A02 | D29: 1
B30: Gadus S2 V220 2_1*770kg_A227 | C30: CE31A02 | D30: 1
B31: Gadus S2 V220 2_1*770kg_A227 | C31: CE35A01 | D31: 1
B32: Gadus S2 V220 2_1*770kg_A227 | C32: CE35A02 | D32: 1
B33: Gadus S2 V220 2_1*770kg_A227 | C33: CE37A01 | D33: 1
A34: 550032917 | B34: Turbo T 46_1*209L_A227 | C34: CB32A02 | D34: 2
B35: Turbo T 46_1*209L_A227 | C35: CD05A01 | D35: 4
B36: Turbo T 46_1*209L_A227 | C36: CE04A02 | D36: 1
A37: 550036050 | B37: Mysella S5 N 40_1*209L_A227 | C37: CB09A01 | D37: 1
A38: 550037752 | B38: Helix HX320W50SLCF_12*1L_A04W | C38: CE24A01 | D38: 19
A39: 550038021 | B39: Helix HX320W50SLCF_4*4L_A04W | C39: CE23A02 | D39: 18
A40: 550041492 | B40: Omala S2 GX 220_1*209L_A227 | C40: CB29A02 | D40: 3
A41: 550044360 | B41: RimR4X15W40CI4E7DH1_1*209L_A227 | C41: CB06A01 | D41: 4
B42: RimR4X15W40CI4E7DH1_1*209L_A227 | C42: CB07A01 | D42: 4
...

Sheet summary near expired
A1: Lokasi | B1: (Multiple Items) | G1: =GETPIVOTDATA("Remain Qty",$A$4)=WMS!W2 -> FALSE
A2: Remain Qty | B2: (Multiple Items)
A4: Sum of Remain Qty
A5: item | B5: Description | C5: Batch | D5: Expired Date | E5: GR date | F5: Aging Expired | G5: Aging day | H5: Total
A6: 550024921 | B6: Spirax S2 G 90_1*209L_A227 | C6: 12600813 | D6: 47494 | E6: 46055 | F6: 3 Year, 4 Month, 10 Days | G6: 6 Month, 30 Days | H6: 3
A7: 550024921 | B7: Spirax S2 G 90_1*209L_A227 | C7: 12657247 | D7: 47619 | E7: 46218 | F7: 3 Year, 8 Month, 15 Days | G7: 1 Month, 17 Days | H7: 8
A8: 550024929 | B8: Spirax S2 A 90_1*209L_A227 | C8: 12659431 | D8: 47626 | E8: 46183 | F8: 3 Year, 8 Month, 22 Days | G8: 2 Month, 22 Days | H8: 2
A9: 550024929 | B9: Spirax S2 A 90_1*209L_A227 | C9: 12633622 | D9: 47572 | E9: 46133 | F9: 3 Year, 6 Month, 29 Days | G9: 4 Month, 11 Days | H9: 2
A10: 550024929 | B10: Spirax S2 A 90_1*209L_A227 | C10: 12668639 | D10: 47654 | E10: 46216 | F10: 3 Year, 9 Month, 19 Days | G10: 1 Month, 19 Days | H10: 4
A11: 550024953 | B11: Corena S4 R 68_1*209L_A227 | C11: 12537758 | D11: 47358 | E11: 46004 | F11: 2 Year, 11 Month, 27 Days | G11: 8 Month, 19 Days | H11: 3
A12: 550024953 | B12: Corena S4 R 68_1*209L_A227 | C12: 12629768 | D12: 47560 | E12: 46162 | F12: 3 Year, 6 Month, 17 Days | G12: 3 Month, 12 Days | H12: 4
A13: 550024953 | B13: Corena S4 R 68_1*209L_A227 | C13: 12645214 | D13: 47593 | E13: 46190 | F13: 3 Year, 7 Month, 19 Days | G13: 2 Month, 15 Days | H13: 2
A14: 550024953 | B14: Corena S4 R 68_1*209L_A227 | C14: 12645214 | D14: 47593 | E14: 46218 | F14: 3 Year, 7 Month, 19 Days | G14: 1 Month, 17 Days | H14: 4
A15: 550024953 | B15: Corena S4 R 68_1*209L_A227 | C15: 12657675 | D15: 47628 | E15: 46258 | F15: 3 Year, 8 Month, 24 Days | G15: 0 Month, 8 Days | H15: 4
A16: 550024992 | B16: Corena S2 P 100_1*209L_A227 | C16: 12605373 | D16: 47510 | E16: 46121 | F16: 3 Year, 4 Month, 26 Days | G16: 4 Month, 23 Days | H16: 1
A17: 550025044 | B17: Spirax S2 A 85W-140_1*209L_A227 | C17: 12663939 | D17: 47642 | E17: 46219 | F17: 3 Year, 9 Month, 7 Days | G17: 1 Month, 16 Days | H17: 2
A18: 550025044 | B18: Spirax S2 A 85W-140_1*209L_A227 | C18: 12653568 | D18: 47609 | E18: 46216 | F18: 3 Year, 8 Month, 5 Days | G18: 1 Month, 19 Days | H18: 1
A19: 550025058 | B19: Spirax S2 G 90_4*4L_A04W | C19: 06A26 | D19: 47489 | E19: 46226 | F19: 3 Year, 4 Month, 5 Days | G19: 1 Month, 9 Days | H19: 6
A20: 550025358 | B20: Spirax S3 G 80W_12*1L_A04W | C20: 17H24 | D20: 46982 | E20: 46048 | F20: 1 Year, 11 Month, 16 Days | G20: 7 Month, 6 Days | H20: 7
A21: 550027043 | B21: Gadus S3 V220C 2_1*18kg_A227 | C21: 12765328 | D21: 47679 | E21: 46258 | F21: 3 Year, 10 Month, 14 Days | G21: 0 Month, 8 Days | H21: 2
A22: 550027259 | B22: Gadus S2 V220 2_1*770kg_A227 | C22: 12652579 | D22: 47550 | E22: 46197 | F22: 3 Year, 6 Month, 7 Days | G22: 2 Month, 8 Days | H22: 3
A23: 550027259 | B23: Gadus S2 V220 2_1*770kg_A227 | C23: 12652579 | D23: 47595 | E23: 46197 | F23: 3 Year, 7 Month, 21 Days | G23: 2 Month, 8 Days | H23: 1
A24: 550027259 | B24: Gadus S2 V220 2_1*770kg_A227 | C24: 12652579 | D24: 47632 | E24: 46197 | F24: 3 Year, 8 Month, 28 Days | G24: 2 Month, 8 Days | H24: 14
A25: 550027259 | B25: Gadus S2 V220 2_1*770kg_A227 | C25: 12652579 | D25: 47606 | E25: 46197 | F25: 3 Year, 8 Month, 2 Days | G25: 2 Month, 8 Days | H25: 1
A26: 550027259 | B26: Gadus S2 V220 2_1*770kg_A227 | C26: 12675312 | D26: 47689 | E26: 46254 | F26: 3 Year, 10 Month, 24 Days | G26: 0 Month, 12 Days | H26: 20
A27: 550027259 | B27: Gadus S2 V220 2_1*770kg_A227 | C27: 12675286 | D27: 47689 | E27: 46253 | F27: 3 Year, 10 Month, 24 Days | G27: 0 Month, 13 Days | H27: 1
A28: 550027259 | B28: Gadus S2 V220 2_1*770kg_A227 | C28: 12652581 | D28: 47632 | E28: 46253 | F28: 3 Year, 8 Month, 28 Days | G28: 0 Month, 13 Days | H28: 19
A29: 550027259 | B29: Gadus S2 V220 2_1*770kg_A227 | C29: 12675289 | D29: 47691 | E29: 46255 | F29: 3 Year, 10 Month, 26 Days | G29: 0 Month, 11 Days | H29: 20
A30: 550027259 | B30: Gadus S2 V220 2_1*770kg_A227 | C30: 12675287 | D30: 47690 | E30: 46258 | F30: 3 Year, 10 Month, 25 Days | G30: 0 Month, 8 Days | H30: 20
A31: 550027259 | B31: Gadus S2 V220 2_1*770kg_A227 | C31: 12688352 | D31: 47703 | E31: 46262 | F31: 3 Year, 11 Month, 7 Days | G31: 0 Month, 4 Days | H31: 20
A32: 550032916 | B32: Turbo T 68_1*209L_A227 | C32: 12658123 | D32: 47626 | E32: 46219 | F32: 3 Year, 8 Month, 22 Days | G32: 1 Month, 16 Days | H32: 4
A33: 550032917 | B33: Turbo T 46_1*209L_A227 | C33: 12649610 | D33: 47595 | E33: 46162 | F33: 3 Year, 7 Month, 21 Days | G33: 3 Month, 12 Days | H33: 2
A34: 550032917 | B34: Turbo T 46_1*209L_A227 | C34: 13D26JJ | D34: 47599 | E34: 46133 | F34: 3 Year, 7 Month, 25 Days | G34: 4 Month, 11 Days | H34: 4
A35: 550032917 | B35: Turbo T 46_1*209L_A227 | C35: 12664083 | D35: 47639 | E35: 46218 | F35: 3 Year, 9 Month, 4 Days | G35: 1 Month, 17 Days | H35: 1
A36: 550032917 | B36: Turbo T 46_1*209L_A227 | C36: 12689981 | D36: 47701 | E36: 46256 | F36: 3 Year, 11 Month, 5 Days | G36: 0 Month, 10 Days | H36: 4
A37: 550036050 | B37: Mysella S5 N 40_1*209L_A227 | C37: 12655616 | D37: 47622 | E37: 46181 | F37: 3 Year, 8 Month, 18 Days | G37: 2 Month, 24 Days | H37: 5
A38: 550036050 | B38: Mysella S5 N 40_1*209L_A227 | C38: 12653546 | D38: 47625 | E38: 46219 | F38: 3 Year, 8 Month, 21 Days | G38: 1 Month, 16 Days | H38: 8
A39: 550036050 | B39: Mysella S5 N 40_1*209L_A227 | C39: 12645194 | D39: 47581 | E39: 46233 | F39: 3 Year, 7 Month, 7 Days | G39: 1 Month, 2 Days | H39: 4
A40: 550037752 | B40: Helix HX320W50SLCF_12*1L_A04W | C40: 24B26JJ | D40: 47538 | E40: 46114 | F40: 3 Year, 5 Month, 23 Days | G40: 4 Month, 30 Days | H40: 2
A41: 550037752 | B41: Helix HX320W50SLCF_12*1L_A04W | C41: 12H26JJ | D41: 47707 | E41: 46260 | F41: 3 Year, 11 Month, 11 Days | G41: 0 Month, 6 Days | H41: 200
...

Sheet RAMCO
B2: unrest | I2: Blok
A3: Bin | B3: Item Code | C3: FISIK | D3: RAMCO | E3: DIFF | I3: Item Code | J3: FISIK | K3: RAMCO | L3: DIFF
A4: CA01A01 | B4: 550049044 | C4: 2 | D4: 2 | E4: =C4-D4 -> 0 | I4: 550038021 | J4: 1 | K4: 1 | L4: =J4-K4 -> 0
A5: CA01A02 | B5: 550054878 | C5: 1 | D5: 1 | E5: =C5-D5 -> 0 | I5: 550045080 | J5: 1 | K5: 1 | L5: =J5-K5 -> 0
A6: CA01B01 | B6: 550027259 | C6: 1 | D6: 1 | E6: =C6-D6 -> 0 | I6: 550049044 | J6: 1 | K6: 1 | L6: =J6-K6 -> 0
A7: CA01B02 | B7: 550027259 | C7: 1 | D7: 1 | E7: =C7-D7 -> 0 | I7: 550050072 | J7: 1 | K7: 1 | L7: =J7-K7 -> 0
A8: CA01C01 | B8: 550070612 | C8: 44 | D8: 44 | E8: =C8-D8 -> 0 | I8: 550058592 | J8: 8 | K8: 8 | L8: =J8-K8 -> 0
A9: CA01C02 | B9: 550054596 | C9: 4 | D9: 4 | E9: =C9-D9 -> 0 | I9: 550058593 | J9: 1 | K9: 1 | L9: =J9-K9 -> 0
A10: CA01D01 | B10: 550062464 | C10: 48 | D10: 48 | E10: =C10-D10 -> 0 | I10: 550062463 | J10: 1 | K10: 1 | L10: =J10-K10 -> 0
A11: CA01D02 | B11: 550062464 | C11: 48 | D11: 48 | E11: =C11-D11 -> 0 | I11: 550062464 | J11: 1 | K11: 1 | L11: =J11-K11 -> 0
A12: CA01E01 | B12: 550062464 | C12: 48 | D12: 48 | E12: =C12-D12 -> 0 | I12: 550069888 | J12: 1 | K12: 1 | L12: =J12-K12 -> 0
A13: CA01E02 | B13: 550062464 | C13: 48 | D13: 48 | E13: =C13-D13 -> 0 | I13: 550070614 | J13: 2 | K13: 2 | L13: =J13-K13 -> 0
A14: CA02A01 | B14: 550062285 | C14: 1 | D14: 1 | E14: =C14-D14 -> 0 | I14: 550071397 | J14: 2 | K14: 2 | L14: =J14-K14 -> 0
A15: CA02A02 | B15: 550062285 | C15: 1 | D15: 1 | E15: =C15-D15 -> 0 | I15: 550043469 | J15: 1 | K15: 1 | L15: =J15-K15 -> 0
A16: CA02B01 | B16: 550062285 | C16: 1 | D16: 1 | E16: =C16-D16 -> 0 | I16: 550053104 | J16: 4 | K16: 4 | L16: =J16-K16 -> 0
A17: CA02B02 | B17: 550062285 | C17: 1 | D17: 1 | E17: =C17-D17 -> 0
A18: CA02C01 | B18: 550062463 | C18: 48 | D18: 48 | E18: =C18-D18 -> 0
A19: CA02C02 | B19: 550062463 | C19: 48 | D19: 48 | E19: =C19-D19 -> 0
A20: CA02D01 | B20: 550062463 | C20: 48 | D20: 48 | E20: =C20-D20 -> 0
A21: CA02D02 | B21: 550062463 | C21: 48 | D21: 48 | E21: =C21-D21 -> 0
A22: CA02E01 | B22: 550062463 | C22: 48 | D22: 48 | E22: =C22-D22 -> 0
A23: CA02E02 | B23: 550047302 | C23: 48 | D23: 48 | E23: =C23-D23 -> 0
A24: CA03A01 | B24: 550061082 | C24: 0 | E24: =C24-D24 -> 0
A25: CA03A02 | B25: 550062285 | C25: 1 | D25: 1 | E25: =C25-D25 -> 0
A26: CA03B01 | B26: 550062285 | C26: 1 | D26: 1 | E26: =C26-D26 -> 0
A27: CA03B02 | B27: 550062285 | C27: 1 | D27: 1 | E27: =C27-D27 -> 0
A28: CA03C01 | B28: 550062464 | C28: 48 | D28: 48 | E28: =C28-D28 -> 0
A29: CA03C02 | B29: 550062464 | C29: 48 | D29: 48 | E29: =C29-D29 -> 0
A30: CA03D01 | B30: 550062464 | C30: 48 | D30: 48 | E30: =C30-D30 -> 0
A31: CA03D02 | B31: 550062464 | C31: 48 | D31: 48 | E31: =C31-D31 -> 0
A32: CA03E01 | B32: 550062464 | C32: 48 | D32: 48 | E32: =C32-D32 -> 0
A33: CA03E02 | B33: 550062464 | C33: 48 | D33: 48 | E33: =C33-D33 -> 0
A34: CA04A01 | B34: 550046498 | C34: 0 | E34: =C34-D34 -> 0
A35: CA04A02 | B35: 550062285 | C35: 1 | D35: 1 | E35: =C35-D35 -> 0
A36: CA04B01 | B36: 550062285 | C36: 1 | D36: 1 | E36: =C36-D36 -> 0
A37: CA04B02 | B37: 550062285 | C37: 1 | D37: 1 | E37: =C37-D37 -> 0
A38: CA04C01 | B38: 550062464 | C38: 48 | D38: 48 | E38: =C38-D38 -> 0
A39: CA04C02 | B39: 550032916 | C39: 4 | D39: 4 | E39: =C39-D39 -> 0
A40: CA04D01 | B40: 550062464 | C40: 48 | D40: 48 | E40: =C40-D40 -> 0
A41: CA04D02 | B41: 550062631 | C41: 44 | D41: 44 | E41: =C41-D41 -> 0
...

Sheet SAP_17 Septber vs fisik_unrest
F1: SAP vs Fisik Accuracy | H1: =COUNTIF($Z$8:$Z$1029,0)/COUNTA($Z$8:$Z$1029) -> 1
F2: Fisik vs RAMCO Accuracy | H2: =COUNTIF($AB$8:$AB$1029,0)/COUNTA($AB$8:$AB$1029) -> 0.27835052 | Y2: cek STAGING
F3: SAP vs RAMCO Accuracy | H3: =COUNTIF($AD$8:$AD$1029,0)/COUNTA($AD$8:$AD$1029) -> 0.27835052
B5: Total SKU : | C5: =COUNTA(B8:B1051) -> 99
G6: SAP | I6: FISIK | K6: RAMCO
A7: Plant | B7: SKU CODE | C7: Material Description | D7: Storage Location | E7: Batch | F7: Base Unit of Measure | G7: Unrestricted | H7: Blocked | I7: Unrestricted | J7: Blocked | K7: Unrestricted | L7: Blocked | M7: Unrest Diff ( SAP vs fisik) | N7: Blok ( SAP vs Fisik) | O7: Unrest Diff ( Fisik vs RAMCO) | P7: Blok ( Fisik vs Ramco) | Q7: Unrest Diff ( SAP vs RAMCO) | R7: Blok ( SAP vs Ramco) | S7: Remarks | T7: cek | U7: Noted | V7: PENDING GI | W7: Previous | X7: cek | Y7: SAP vs fisik | Z7: SAP vs fisik Accuracy | AA7: Fisik vs RAMCO | AB7: Fisik vs RAMCO Accuracy | AC7: SAP vs RAMCO | AD7: SAP vs RAMCO Accuracy | AE7: Selisih ALL | AF7: CEK SELISIH
A8: I003 | B8: 550058592 | C8: Adv4TAX515W40SLMA2_12*1L_A04W | D8: WHS1 | E8: UT | F8: CAR | G8: 2363 | H8: 8 | I8: =SUMIF(WMS!$L$5:$L$2606,B8,WMS!$AE$5:$AE$2606) -> 2363 | J8: =SUMIF(WMS!$L$2607:$L$2619,'SAP_17 Septber vs fisik_unrest'!B8,WMS!$AE$2607:$AE$2619) -> 8 | K8: =SUMIF(RAMCO!$B$4:$B$21630,'SAP_17 Septber vs fisik_unrest'!B8,RAMCO!$D$4:$D$21630) -> 2054 | L8: =SUMIF(RAMCO!$I$4:$I$150,'SAP_17 Septber vs fisik_unrest'!B8,RAMCO!$K$4:$K$150) -> 8 | M8: =G8-I8 -> 0 | N8: =H8-J8 -> 0 | O8: =I8-K8 -> 309 | P8: =J8-L8 -> 0 | Q8: =G8-K8 -> 309 | R8: =H8-L8 -> 0 | X8: =COUNTIF($B$8:$B$1042,B8) -> 1 | Y8: =IF(OR(M8<>0,N8<>0),"selisih","ok") -> ok | Z8: =SUM($I8:$J8)-SUM($G8:$H8) -> 0 | AA8: =IF(OR(O8<>0,P8<>0),"selisih","ok") -> selisih | AB8: =SUM($I8:$J8)-SUM($K8:$L8) -> 309 | AC8: =IF(OR(Q8<>0,R8<>0),"selisih","ok") -> selisih | AD8: =SUM($G8:$H8)-SUM($K8:$L8) -> 309 | AE8: =IF(OR(Y8="selisih",AA8="selisih",AC8="selisih"),"cek","") -> cek | AF8: =I8-G8 -> 0
A9: I003 | B9: 550053104 | C9: HelixAst5W30_SP_12*1L_A04W | D9: WHS1 | E9: UT | F9: CAR | G9: 333 | H9: 4 | I9: =SUMIF(WMS!$L$5:$L$2606,B9,WMS!$AE$5:$AE$2606) -> 333 | J9: =SUMIF(WMS!$L$2607:$L$2619,'SAP_17 Septber vs fisik_unrest'!B9,WMS!$AE$2607:$AE$2619) -> 4 | K9: =SUMIF(RAMCO!$B$4:$B$21630,'SAP_17 Septber vs fisik_unrest'!B9,RAMCO!$D$4:$D$21630) -> 0 | L9: =SUMIF(RAMCO!$I$4:$I$150,'SAP_17 Septber vs fisik_unrest'!B9,RAMCO!$K$4:$K$150) -> 4 | M9: =G9-I9 -> 0 | N9: =H9-J9 -> 0 | O9: =I9-K9 -> 333 | P9: =J9-L9 -> 0 | Q9: =G9-K9 -> 333 | R9: =H9-L9 -> 0 | X9: =COUNTIF($B$8:$B$1042,B9) -> 1 | Y9: =IF(OR(M9<>0,N9<>0),"selisih","ok") -> ok | Z9: =SUM($I9:$J9)-SUM($G9:$H9) -> 0 | AA9: =IF(OR(O9<>0,P9<>0),"selisih","ok") -> selisih | AB9: =SUM($I9:$J9)-SUM($K9:$L9) -> 333 | AC9: =IF(OR(Q9<>0,R9<>0),"selisih","ok") -> selisih | AD9: =SUM($G9:$H9)-SUM($K9:$L9) -> 333 | AE9: =IF(OR(Y9="selisih",AA9="selisih",AC9="selisih"),"cek","") -> cek | AF9: =I9-G9 -> 0
A10: I003 | B10: 550071397 | C10: HelixHX515W40SNCF_4*4L_A04W | D10: WHS1 | E10: UT | F10: CAR | G10: 3005 | H10: 3 | I10: =SUMIF(WMS!$L$5:$L$2606,B10,WMS!$AE$5:$AE$2606) -> 3005 | J10: =SUMIF(WMS!$L$2607:$L$2619,'SAP_17 Septber vs fisik_unrest'!B10,WMS!$AE$2607:$AE$2619) -> 3 | K10: =SUMIF(RAMCO!$B$4:$B$21630,'SAP_17 Septber vs fisik_unrest'!B10,RAMCO!$D$4:$D$21630) -> 562 | L10: =SUMIF(RAMCO!$I$4:$I$150,'SAP_17 Septber vs fisik_unrest'!B10,RAMCO!$K$4:$K$150) -> 2 | M10: =G10-I10 -> 0 | N10: =H10-J10 -> 0 | O10: =I10-K10 -> 2443 | P10: =J10-L10 -> 1 | Q10: =G10-K10 -> 2443 | R10: =H10-L10 -> 1 | X10: =COUNTIF($B$8:$B$1042,B10) -> 1 | Y10: =IF(OR(M10<>0,N10<>0),"selisih","ok") -> ok | Z10: =SUM($I10:$J10)-SUM($G10:$H10) -> 0 | AA10: =IF(OR(O10<>0,P10<>0),"selisih","ok") -> selisih | AB10: =SUM($I10:$J10)-SUM($K10:$L10) -> 2444 | AC10: =IF(OR(Q10<>0,R10<>0),"selisih","ok") -> selisih | AD10: =SUM($G10:$H10)-SUM($K10:$L10) -> 2444 | AE10: =IF(OR(Y10="selisih",AA10="selisih",AC10="selisih"),"cek","") -> cek | AF10: =I10-G10 -> 0
A11: I003 | B11: 550070614 | C11: HlxHX610W40SP_4*4L_A04W | D11: WHS1 | E11: UT | F11: CAR | G11: 5477 | H11: 2 | I11: =SUMIF(WMS!$L$5:$L$2606,B11,WMS!$AE$5:$AE$2606) -> 5476 | J11: =SUMIF(WMS!$L$2607:$L$2619,'SAP_17 Septber vs fisik_unrest'!B11,WMS!$AE$2607:$AE$2619) -> 3 | K11: =SUMIF(RAMCO!$B$4:$B$21630,'SAP_17 Septber vs fisik_unrest'!B11,RAMCO!$D$4:$D$21630) -> 2122 | L11: =SUMIF(RAMCO!$I$4:$I$150,'SAP_17 Septber vs fisik_unrest'!B11,RAMCO!$K$4:$K$150) -> 2 | M11: =G11-I11 -> 1 | N11: =H11-J11 -> -1 | O11: =I11-K11 -> 3354 | P11: =J11-L11 -> 1 | Q11: =G11-K11 -> 3355 | R11: =H11-L11 -> 0 | X11: =COUNTIF($B$8:$B$1042,B11) -> 1 | Y11: =IF(OR(M11<>0,N11<>0),"selisih","ok") -> selisih | Z11: =SUM($I11:$J11)-SUM($G11:$H11) -> 0 | AA11: =IF(OR(O11<>0,P11<>0),"selisih","ok") -> selisih | AB11: =SUM($I11:$J11)-SUM($K11:$L11) -> 3355 | AC11: =IF(OR(Q11<>0,R11<>0),"selisih","ok") -> selisih | AD11: =SUM($G11:$H11)-SUM($K11:$L11) -> 3355 | AE11: =IF(OR(Y11="selisih",AA11="selisih",AC11="selisih"),"cek","") -> cek | AF11: =I11-G11 -> -1
A12: I003 | B12: 550038021 | C12: Helix HX320W50SLCF_4*4L_A04W | D12: WHS1 | E12: UT | F12: CAR | G12: 112 | H12: 1 | I12: =SUMIF(WMS!$L$5:$L$2606,B12,WMS!$AE$5:$AE$2606) -> 112 | J12: =SUMIF(WMS!$L$2607:$L$2619,'SAP_17 Septber vs fisik_unrest'!B12,WMS!$AE$2607:$AE$2619) -> 1 | K12: =SUMIF(RAMCO!$B$4:$B$21630,'SAP_17 Septber vs fisik_unrest'!B12,RAMCO!$D$4:$D$21630) -> 1153 | L12: =SUMIF(RAMCO!$I$4:$I$150,'SAP_17 Septber vs fisik_unrest'!B12,RAMCO!$K$4:$K$150) -> 1 | M12: =G12-I12 -> 0 | N12: =H12-J12 -> 0 | O12: =I12-K12 -> -1041 | P12: =J12-L12 -> 0 | Q12: =G12-K12 -> -1041 | R12: =H12-L12 -> 0 | X12: =COUNTIF($B$8:$B$1042,B12) -> 1 | Y12: =IF(OR(M12<>0,N12<>0),"selisih","ok") -> ok | Z12: =SUM($I12:$J12)-SUM($G12:$H12) -> 0 | AA12: =IF(OR(O12<>0,P12<>0),"selisih","ok") -> selisih | AB12: =SUM($I12:$J12)-SUM($K12:$L12) -> -1041 | AC12: =IF(OR(Q12<>0,R12<>0),"selisih","ok") -> selisih | AD12: =SUM($G12:$H12)-SUM($K12:$L12) -> -1041 | AE12: =IF(OR(Y12="selisih",AA12="selisih",AC12="selisih"),"cek","") -> cek | AF12: =I12-G12 -> 0
A13: I003 | B13: 550043469 | C13: HelixAstraSN10W30_12*1L_A04W | D13: WHS1 | E13: UT | F13: CAR | G13: 485 | H13: 1 | I13: =SUMIF(WMS!$L$5:$L$2606,B13,WMS!$AE$5:$AE$2606) -> 485 | J13: =SUMIF(WMS!$L$2607:$L$2619,'SAP_17 Septber vs fisik_unrest'!B13,WMS!$AE$2607:$AE$2619) -> 1 | K13: =SUMIF(RAMCO!$B$4:$B$21630,'SAP_17 Septber vs fisik_unrest'!B13,RAMCO!$D$4:$D$21630) -> 0 | L13: =SUMIF(RAMCO!$I$4:$I$150,'SAP_17 Septber vs fisik_unrest'!B13,RAMCO!$K$4:$K$150) -> 1 | M13: =G13-I13 -> 0 | N13: =H13-J13 -> 0 | O13: =I13-K13 -> 485 | P13: =J13-L13 -> 0 | Q13: =G13-K13 -> 485 | R13: =H13-L13 -> 0 | X13: =COUNTIF($B$8:$B$1042,B13) -> 1 | Y13: =IF(OR(M13<>0,N13<>0),"selisih","ok") -> ok | Z13: =SUM($I13:$J13)-SUM($G13:$H13) -> 0 | AA13: =IF(OR(O13<>0,P13<>0),"selisih","ok") -> selisih | AB13: =SUM($I13:$J13)-SUM($K13:$L13) -> 485 | AC13: =IF(OR(Q13<>0,R13<>0),"selisih","ok") -> selisih | AD13: =SUM($G13:$H13)-SUM($K13:$L13) -> 485 | AE13: =IF(OR(Y13="selisih",AA13="selisih",AC13="selisih"),"cek","") -> cek | AF13: =I13-G13 -> 0
A14: I003 | B14: 550045080 | C14: Tellus S2 MX 68_1*209L_A227 | D14: WHS1 | E14: UT | F14: EA | G14: 116 | H14: 1 | I14: =SUMIF(WMS!$L$5:$L$2606,B14,WMS!$AE$5:$AE$2606) -> 116 | J14: =SUMIF(WMS!$L$2607:$L$2619,'SAP_17 Septber vs fisik_unrest'!B14,WMS!$AE$2607:$AE$2619) -> 1 | K14: =SUMIF(RAMCO!$B$4:$B$21630,'SAP_17 Septber vs fisik_unrest'!B14,RAMCO!$D$4:$D$21630) -> 117 | L14: =SUMIF(RAMCO!$I$4:$I$150,'SAP_17 Septber vs fisik_unrest'!B14,RAMCO!$K$4:$K$150) -> 1 | M14: =G14-I14 -> 0 | N14: =H14-J14 -> 0 | O14: =I14-K14 -> -1 | P14: =J14-L14 -> 0 | Q14: =G14-K14 -> -1 | R14: =H14-L14 -> 0 | X14: =COUNTIF($B$8:$B$1042,B14) -> 1 | Y14: =IF(OR(M14<>0,N14<>0),"selisih","ok") -> ok | Z14: =SUM($I14:$J14)-SUM($G14:$H14) -> 0 | AA14: =IF(OR(O14<>0,P14<>0),"selisih","ok") -> selisih | AB14: =SUM($I14:$J14)-SUM($K14:$L14) -> -1 | AC14: =IF(OR(Q14<>0,R14<>0),"selisih","ok") -> selisih | AD14: =SUM($G14:$H14)-SUM($K14:$L14) -> -1 | AE14: =IF(OR(Y14="selisih",AA14="selisih",AC14="selisih"),"cek","") -> cek | AF14: =I14-G14 -> 0
A15: I003 | B15: 550049044 | C15: Advanc4TAX320W50SGMA_12*1L_A04W | D15: WHS1 | E15: UT | F15: CAR | G15: 75 | H15: 1 | I15: =SUMIF(WMS!$L$5:$L$2606,B15,WMS!$AE$5:$AE$2606) -> 75 | J15: =SUMIF(WMS!$L$2607:$L$2619,'SAP_17 Septber vs fisik_unrest'!B15,WMS!$AE$2607:$AE$2619) -> 1 | K15: =SUMIF(RAMCO!$B$4:$B$21630,'SAP_17 Septber vs fisik_unrest'!B15,RAMCO!$D$4:$D$21630) -> 203 | L15: =SUMIF(RAMCO!$I$4:$I$150,'SAP_17 Septber vs fisik_unrest'!B15,RAMCO!$K$4:$K$150) -> 1 | M15: =G15-I15 -> 0 | N15: =H15-J15 -> 0 | O15: =I15-K15 -> -128 | P15: =J15-L15 -> 0 | Q15: =G15-K15 -> -128 | R15: =H15-L15 -> 0 | X15: =COUNTIF($B$8:$B$1042,B15) -> 1 | Y15: =IF(OR(M15<>0,N15<>0),"selisih","ok") -> ok | Z15: =SUM($I15:$J15)-SUM($G15:$H15) -> 0 | AA15: =IF(OR(O15<>0,P15<>0),"selisih","ok") -> selisih | AB15: =SUM($I15:$J15)-SUM($K15:$L15) -> -128 | AC15: =IF(OR(Q15<>0,R15<>0),"selisih","ok") -> selisih | AD15: =SUM($G15:$H15)-SUM($K15:$L15) -> -128 | AE15: =IF(OR(Y15="selisih",AA15="selisih",AC15="selisih"),"cek","") -> cek | AF15: =I15-G15 -> 0
A16: I003 | B16: 550050072 | C16: RimLD4Extra15W40CI4_3*5L_A04W | D16: WHS1 | E16: UT | F16: CAR | G16: 26 | H16: 1 | I16: =SUMIF(WMS!$L$5:$L$2606,B16,WMS!$AE$5:$AE$2606) -> 26 | J16: =SUMIF(WMS!$L$2607:$L$2619,'SAP_17 Septber vs fisik_unrest'!B16,WMS!$AE$2607:$AE$2619) -> 1 | K16: =SUMIF(RAMCO!$B$4:$B$21630,'SAP_17 Septber vs fisik_unrest'!B16,RAMCO!$D$4:$D$21630) -> 548 | L16: =SUMIF(RAMCO!$I$4:$I$150,'SAP_17 Septber vs fisik_unrest'!B16,RAMCO!$K$4:$K$150) -> 1 | M16: =G16-I16 -> 0 | N16: =H16-J16 -> 0 | O16: =I16-K16 -> -522 | P16: =J16-L16 -> 0 | Q16: =G16-K16 -> -522 | R16: =H16-L16 -> 0 | X16: =COUNTIF($B$8:$B$1042,B16) -> 1 | Y16: =IF(OR(M16<>0,N16<>0),"selisih","ok") -> ok | Z16: =SUM($I16:$J16)-SUM($G16:$H16) -> 0 | AA16: =IF(OR(O16<>0,P16<>0),"selisih","ok") -> selisih | AB16: =SUM($I16:$J16)-SUM($K16:$L16) -> -522 | AC16: =IF(OR(Q16<>0,R16<>0),"selisih","ok") -> selisih | AD16: =SUM($G16:$H16)-SUM($K16:$L16) -> -522 | AE16: =IF(OR(Y16="selisih",AA16="selisih",AC16="selisih"),"cek","") -> cek | AF16: =I16-G16 -> 0
A17: I003 | B17: 550058593 | C17: Adv4TAX515W40SLMA2_12*0.8L_A04W | D17: WHS1 | E17: UT | F17: CAR | G17: 5207 | H17: 1 | I17: =SUMIF(WMS!$L$5:$L$2606,B17,WMS!$AE$5:$AE$2606) -> 5207 | J17: =SUMIF(WMS!$L$2607:$L$2619,'SAP_17 Septber vs fisik_unrest'!B17,WMS!$AE$2607:$AE$2619) -> 1 | K17: =SUMIF(RAMCO!$B$4:$B$21630,'SAP_17 Septber vs fisik_unrest'!B17,RAMCO!$D$4:$D$21630) -> 5375 | L17: =SUMIF(RAMCO!$I$4:$I$150,'SAP_17 Septber vs fisik_unrest'!B17,RAMCO!$K$4:$K$150) -> 1 | M17: =G17-I17 -> 0 | N17: =H17-J17 -> 0 | O17: =I17-K17 -> -168 | P17: =J17-L17 -> 0 | Q17: =G17-K17 -> -168 | R17: =H17-L17 -> 0 | X17: =COUNTIF($B$8:$B$1042,B17) -> 1 | Y17: =IF(OR(M17<>0,N17<>0),"selisih","ok") -> ok | Z17: =SUM($I17:$J17)-SUM($G17:$H17) -> 0 | AA17: =IF(OR(O17<>0,P17<>0),"selisih","ok") -> selisih | AB17: =SUM($I17:$J17)-SUM($K17:$L17) -> -168 | AC17: =IF(OR(Q17<>0,R17<>0),"selisih","ok") -> selisih | AD17: =SUM($G17:$H17)-SUM($K17:$L17) -> -168 | AE17: =IF(OR(Y17="selisih",AA17="selisih",AC17="selisih"),"cek","") -> cek | AF17: =I17-G17 -> 0
A18: I003 | B18: 550062463 | C18: AdvAX7Sc10W40SNMB_12*0.8L_A04W | D18: WHS1 | E18: UT | F18: CAR | G18: 960 | H18: 1 | I18: =SUMIF(WMS!$L$5:$L$2606,B18,WMS!$AE$5:$AE$2606) -> 960 | J18: =SUMIF(WMS!$L$2607:$L$2619,'SAP_17 Septber vs fisik_unrest'!B18,WMS!$AE$2607:$AE$2619) -> 1 | K18: =SUMIF(RAMCO!$B$4:$B$21630,'SAP_17 Septber vs fisik_unrest'!B18,RAMCO!$D$4:$D$21630) -> 4673 | L18: =SUMIF(RAMCO!$I$4:$I$150,'SAP_17 Septber vs fisik_unrest'!B18,RAMCO!$K$4:$K$150) -> 1 | M18: =G18-I18 -> 0 | N18: =H18-J18 -> 0 | O18: =I18-K18 -> -3713 | P18: =J18-L18 -> 0 | Q18: =G18-K18 -> -3713 | R18: =H18-L18 -> 0 | X18: =COUNTIF($B$8:$B$1042,B18) -> 1 | Y18: =IF(OR(M18<>0,N18<>0),"selisih","ok") -> ok | Z18: =SUM($I18:$J18)-SUM($G18:$H18) -> 0 | AA18: =IF(OR(O18<>0,P18<>0),"selisih","ok") -> selisih | AB18: =SUM($I18:$J18)-SUM($K18:$L18) -> -3713 | AC18: =IF(OR(Q18<>0,R18<>0),"selisih","ok") -> selisih | AD18: =SUM($G18:$H18)-SUM($K18:$L18) -> -3713 | AE18: =IF(OR(Y18="selisih",AA18="selisih",AC18="selisih"),"cek","") -> cek | AF18: =I18-G18 -> 0
A19: I003 | B19: 550062464 | C19: Adv4TAX7Sc10W30SNMB_12*0.8L_A04W | D19: WHS1 | E19: UT | F19: CAR | G19: 2273 | H19: 1 | I19: =SUMIF(WMS!$L$5:$L$2606,B19,WMS!$AE$5:$AE$2606) -> 2273 | J19: =SUMIF(WMS!$L$2607:$L$2619,'SAP_17 Septber vs fisik_unrest'!B19,WMS!$AE$2607:$AE$2619) -> 1 | K19: =SUMIF(RAMCO!$B$4:$B$21630,'SAP_17 Septber vs fisik_unrest'!B19,RAMCO!$D$4:$D$21630) -> 5140 | L19: =SUMIF(RAMCO!$I$4:$I$150,'SAP_17 Septber vs fisik_unrest'!B19,RAMCO!$K$4:$K$150) -> 1 | M19: =G19-I19 -> 0 | N19: =H19-J19 -> 0 | O19: =I19-K19 -> -2867 | P19: =J19-L19 -> 0 | Q19: =G19-K19 -> -2867 | R19: =H19-L19 -> 0 | X19: =COUNTIF($B$8:$B$1042,B19) -> 1 | Y19: =IF(OR(M19<>0,N19<>0),"selisih","ok") -> ok | Z19: =SUM($I19:$J19)-SUM($G19:$H19) -> 0 | AA19: =IF(OR(O19<>0,P19<>0),"selisih","ok") -> selisih | AB19: =SUM($I19:$J19)-SUM($K19:$L19) -> -2867 | AC19: =IF(OR(Q19<>0,R19<>0),"selisih","ok") -> selisih | AD19: =SUM($G19:$H19)-SUM($K19:$L19) -> -2867 | AE19: =IF(OR(Y19="selisih",AA19="selisih",AC19="selisih"),"cek","") -> cek | AF19: =I19-G19 -> 0
... A104: I003 | B104: 550077627 | C104: HelixUltraECT5W30_12*1L_A04W | D104: WHS1 | E104: UT | F104: CAR | G104: 34 | H104: 0 | I104: =SUMIF(WMS!$L$5:$L$2606,B104,WMS!$AE$5:$AE$2606) -> 34 | J104: =SUMIF(WMS!$L$2607:$L$2619,'SAP_17 Septber vs fisik_unrest'!B104,WMS!$AE$2607:$AE$2619) -> 0 | K104: =SUMIF(RAMCO!$B$4:$B$21630,'SAP_17 Septber vs fisik_unrest'!B104,RAMCO!$D$4:$D$21630) -> 0 | L104: =SUMIF(RAMCO!$I$4:$I$150,'SAP_17 Septber vs fisik_unrest'!B104,RAMCO!$K$4:$K$150) -> 0 | M104: =G104-I104 -> 0 | N104: =H104-J104 -> 0 | O104: =I104-K104 -> 34 | P104: =J104-L104 -> 0 | Q104: =G104-K104 -> 34 | R104: =H104-L104 -> 0 | X104: =COUNTIF($B$8:$B$1042,B104) -> 1 | Y104: =IF(OR(M104<>0,N104<>0),"selisih","ok") -> ok | Z104: =SUM($I104:$J104)-SUM($G104:$H104) -> 0 | AA104: =IF(OR(O104<>0,P104<>0),"selisih","ok") -> selisih | AB104: =SUM($I104:$J104)-SUM($K104:$L104) -> 34 | AC104: =IF(OR(Q104<>0,R104<>0),"selisih","ok") -> selisih | AD104: =SUM($G104:$H104)-SUM($K104:$L104) -> 34 | AE104: =IF(OR(Y104="selisih",AA104="selisih",AC104="selisih"),"cek","") -> cek | AF104: =I104-G104 -> 0
A105: I003 | B105: 550077926 | C105: HlxHX610W30SP_12*1L_A04W | D105: WHS1 | E105: UT | F105: CAR | G105: 100 | H105: 0 | I105: =SUMIF(WMS!$L$5:$L$2606,B105,WMS!$AE$5:$AE$2606) -> 100 | J105: =SUMIF(WMS!$L$2607:$L$2619,'SAP_17 Septber vs fisik_unrest'!B105,WMS!$AE$2607:$AE$2619) -> 0 | Z105: =SUM($I105:$J105)-SUM($G105:$H105) -> 0
A106: I003 | B106: 550077927 | C106: HlxHX610W30SP_4*4L_A04W | D106: WHS1 | E106: UT | F106: CAR | G106: 55 | H106: 0 | I106: =SUMIF(WMS!$L$5:$L$2606,B106,WMS!$AE$5:$AE$2606) -> 55 | J106: =SUMIF(WMS!$L$2607:$L$2619,'SAP_17 Septber vs fisik_unrest'!B106,WMS!$AE$2607:$AE$2619) -> 0 | Z106: =SUM($I106:$J106)-SUM($G106:$H106) -> 0
S114: s
N306: 15
V2529: 16

Sheet data putaway
A1: BIN Location | B1: Item Code | C1: ACTUAL QTY | D1: Batch No | E1: Expired Date | F1: cek dobel
A2: CF21B01 | B2: 550025024 | C2: 4 | D2: 12658898 | E2: 47617 | F2: =COUNTIF($A$2:$A$1410,A2) -> 1
A3: CF13A01 | B3: 550025024 | C3: 1 | D3: 12658898 | E3: 47617 | F3: =COUNTIF($A$2:$A$1410,A3) -> 1
A4: CE36A01 | B4: 550072297 | C4: 9 | D4: 16C26JJ | E4: 47558 | F4: =COUNTIF($A$2:$A$1410,A4) -> 1
A5: CF23C01 | B5: 550025044 | C5: 4 | D5: 1270429 | E5: 47735 | F5: =COUNTIF($A$2:$A$1410,A5) -> 1
A6: CF23C02 | B6: 550025044 | C6: 4 | D6: 1270429 | E6: 47735 | F6: =COUNTIF($A$2:$A$1410,A6) -> 1
A7: CF30B01 | B7: 550025044 | C7: 4 | D7: 1270429 | E7: 47735 | F7: =COUNTIF($A$2:$A$1410,A7) -> 1
A8: CF30B02 | B8: 550025044 | C8: 4 | D8: 1270429 | E8: 47735 | F8: =COUNTIF($A$2:$A$1410,A8) -> 1
A9: CE30A01 | B9: 550025044 | C9: 1 | D9: 1270429 | E9: 47735 | F9: =COUNTIF($A$2:$A$1410,A9) -> 1
A10: CE32A01 | B10: 550075433 | C10: 40 | D10: 29D26JJ | E10: 47602 | F10: =COUNTIF($A$2:$A$1410,A10) -> 1
A11: CF15A01 | B11: 550075434 | C11: 13 | D11: 01D26JJ | E11: 47574 | F11: =COUNTIF($A$2:$A$1410,A11) -> 1
A12: CF15A02 | B12: 550076636 | C12: 38 | D12: 05I26JJ | E12: 47731 | F12: =COUNTIF($A$2:$A$1410,A12) -> 1
A13: CE35A01 | B13: 550050072 | C13: 26 | D13: 24H26JJ | E13: 47719 | F13: =COUNTIF($A$2:$A$1410,A13) -> 1
... A64: CC17E02 | B64: 550069888 | C64: 36 | D64: 12I26JJ | E64: 47738 | F64: =COUNTIF($A$2:$A$1410,A64) -> 1
A65: CF14C01 | B65: 550044360 | C65: 4 | D65: 12704140 | E65: 47736 | F65: =COUNTIF($A$2:$A$1410,A65) -> 1
A66: CF14C02 | B66: 550044360 | C66: 4 | D66: 12704140 | E66: 47736 | F66: =COUNTIF($A$2:$A$1410,A66) -> 1
A67: CF17B01 | B67: 550044360 | C67: 4 | D67: 12704140 | E67: 47736 | F67: =COUNTIF($A$2:$A$1410,A67) -> 1
A68: CF17B02 | B68: 550044360 | C68: 4 | D68: 12704140 | E68: 47736 | F68: =COUNTIF($A$2:$A$1410,A68) -> 1
A69: CF31B01 | B69: 550044360 | C69: 4 | D69: 12704140 | E69: 47736 | F69: =COUNTIF($A$2:$A$1410,A69) -> 1
A70: CF31B02 | B70: 550044360 | C70: 4 | D70: 12704140 | E70: 47736 | F70: =COUNTIF($A$2:$A$1410,A70) -> 1
A71: CF32B01 | B71: 550044360 | C71: 4 | D71: 12704140 | E71: 47736 | F71: =COUNTIF($A$2:$A$1410,A71) -> 1
A72: CF32B02 | B72: 550044360 | C72: 4 | D72: 12704140 | E72: 47736 | F72: =COUNTIF($A$2:$A$1410,A72) -> 1
A73: CF33B01 | B73: 550044360 | C73: 4 | D73: 12704140 | E73: 47736 | F73: =COUNTIF($A$2:$A$1410,A73) -> 1
A74: CF33B02 | B74: 550044360 | C74: 4 | D74: 12704140 | E74: 47736 | F74: =COUNTIF($A$2:$A$1410,A74) -> 1
A75: CF33C01 | B75: 550044360 | C75: 4 | D75: 12704140 | E75: 47736 | F75: =COUNTIF($A$2:$A$1410,A75) -> 1
A76: CF33C02 | B76: 550044360 | C76: 4 | D76: 12704140 | E76: 47736 | F76: =COUNTIF($A$2:$A$1410,A76) -> 1
... A84: CF35C02 | B84: 550044360 | C84: 4 | D84: 12704140 | E84: 47736 | F84: =COUNTIF($A$2:$A$1410,A84) -> 1
A85: CE01D01 | B85: 550053104 | C85: 44 | D85: 23H26JJ | E85: 47718 | F85: =COUNTIF($A$2:$A$1410,A85) -> 1
A86: CE01D02 | B86: 550053104 | C86: 44 | D86: 23H26JJ | E86: 47718 | F86: =COUNTIF($A$2:$A$1410,A86) -> 1
A87: CE02E01 | B87: 550053104 | C87: 44 | D87: 23H26JJ | E87: 47718 | F87: =COUNTIF($A$2:$A$1410,A87) -> 1
A88: CE01E01 | B88: 550053104 | C88: 44 | D88: 23H26JJ | E88: 47718 | F88: =COUNTIF($A$2:$A$1410,A88) -> 1
A89: CE04D02 | B89: 550053104 | C89: 44 | D89: 23H26JJ | E89: 47718 | F89: =COUNTIF($A$2:$A$1410,A89) -> 1
A90: CC22C01 | B90: 550053104 | C90: 44 | D90: 23H26JJ | E90: 47718 | F90: =COUNTIF($A$2:$A$1410,A90) -> 1
A91: CC22C02 | B91: 550053104 | C91: 44 | D91: 23H26JJ | E91: 47718 | F91: =COUNTIF($A$2:$A$1410,A91) -> 1
A92: CC02A02 | B92: 550053104 | C92: 25 | D92: 23H26JJ | E92: 47718 | F92: =COUNTIF($A$2:$A$1410,A92) -> 1
A93: CC02A01 | B93: 550077627 | C93: 34 | D93: 10D26JJ | E93: 47583 | F93: =COUNTIF($A$2:$A$1410,A93) -> 1
A94: CE01C01 | B94: 550054879 | C94: 4 | D94: 12694100 | E94: 47722 | F94: =COUNTIF($A$2:$A$1410,A94) -> 1
A95: CE01C02 | B95: 550054879 | C95: 4 | D95: 12694100 | E95: 47722 | F95: =COUNTIF($A$2:$A$1410,A95) -> 1
A96: CE02B01 | B96: 550054879 | C96: 4 | D96: 12694100 | E96: 47722 | F96: =COUNTIF($A$2:$A$1410,A96) -> 1
A97: CE02C02 | B97: 550054879 | C97: 4 | D97: 12694100 | E97: 47722 | F97: =COUNTIF($A$2:$A$1410,A97) -> 1
...

Sheet WMS
H1: CB32D02 | I1: CE25A02 | L1: ='SAP_17 Septber vs fisik_unrest'!H1 -> 1 | M1: =(44*8) -> 352 | R1: 4 | U1: b out | V1: b in'
H2: STG_INB01 | M2: b out | N2: b in' | O2: 47654 | P2: 550058593 | V2: =SUM(V5:V2564) -> 53998 | W2: =SUM(V5:V2564) -> 53998 | AG2: Total liter | AH2: =SUM(AH5:AH1764) -> 889857.04
A3: CE02A01 | B3: CF23A02 | C3: 550062284 | H3: STG_INB02 | I3: 05I26JJ | J3: 46277 | K3: 47731 | L3: 550069888 | M3: 36 | R3: =SUM(R5:R25965) -> 0 | V3: =COUNTIF($V$5:$V$2564,"<0") -> 0 | AD3: sampai rak CE | AE3: =SUM(AE5:AE2564) -> 53998 | AF3: =SUM(AF5:AF1764) -> 1548 | AG3: =COUNTIF($AI$5:$AI$2564,"aktif") -> 2160 | AH3: =AF3/AG3 -> 0.71666667
A4: xxx | B4: PICK & B OT | C4: IN & put | D4: aisle | E4: level | F4: gg | G4: nomer | H4: Lokasi | I4: Batch | J4: GR date | K4: Expired Date | L4: item | M4: Description | N4: Qty | O4: Palet | P4: Eceran | Q4: UPP | R4: PICK | S4: b out | T4: b in' | U4: putaway | V4: Remain Qty | W4: SKU | X4: CEK | Y4: Batch No | Z4: Exp Date | AA4: cek | AB4: cek | AC4: Aging day | AD4: Aging Expired | AE4: on hand | AF4: PP | AG4: TOTAL LOKSI | AH4: Volume | AI4: status | AJ4: lokasi kosong | AK4: lokasi kosong_1 | AL4: uom | AM4: cek dobe; | AN4: CEK
A5: =H5&L5 -> CA01A01550049044 | B5: =R5+S5 -> 0 | C5: =T5+U5 -> 0 | D5: =LEFT(H5,2) -> CA | E5: =MID(H5,3,2) -> 01 | F5: =MID(H5,5,1) -> A | G5: =RIGHT(H5,2) -> 01 | H5: CA01A01 | I5: 07H26JJ | J5: 46255 | K5: 47702 | L5: 550049044 | M5: =IF(ISNA(VLOOKUP(L5,'MASTER DATA'!$A$1:$B$192,2,0)),"",VLOOKUP(L5,'MASTER DATA'!$A$1:$B$192,2,0)) -> Advanc4TAX320W50SGMA_12*1L_A04W | N5: 0 | O5: =(V5-P5)/Q5 -> 0 | P5: =MOD(V5,Q5) -> 0 | Q5: =VLOOKUP(L5,'MASTER DATA'!$A$1:$E$192,5,0) -> 44 | R5: =SUMIF('picking of the day'!$H$4:$H$358,WMS!H5&WMS!L5,'picking of the day'!$E$4:$E$358) -> 0 | U5: =IF(ISNA(VLOOKUP(H5,'data putaway'!$A$1:$E$530,3,0)),0,VLOOKUP(H5,'data putaway'!$A$1:$E$530,3,0)) -> 0 | V5: =(N5+T5+U5)-(R5+S5) -> 0 | W5: =IF(ISNA(VLOOKUP(H5,'data putaway'!$A$1:$E$530,2,0)),0,VLOOKUP(H5,'data putaway'!$A$1:$E$530,2,0)) -> 0 | X5: =W5=L5 -> FALSE | Y5: =IF(ISNA(VLOOKUP(H5,'data putaway'!$A$1:$E$530,4,0)),0,VLOOKUP(H5,'data putaway'!$A$1:$E$530,4,0)) -> 0 | Z5: =IF(ISNA(VLOOKUP(H5,'data putaway'!$A$1:$E$530,5,0)),0,VLOOKUP(H5,'data putaway'!$A$1:$E$530,5,0)) -> 0 | AA5: =Y5=I5 -> FALSE | AB5: =Z5=K5 -> FALSE | AC5: =IF(J5="","",DATEDIF(J5,NOW(),"ym")&" Month"&", "&DATEDIF(J5,NOW(),"md")&" Days") -> 0 Month, 28 Days | AD5: =IF(K5="","",DATEDIF(NOW(),K5,"y")&" Year"&", "&DATEDIF(NOW(),K5,"ym")&" Month"&", "&DATEDIF(NOW(),K5,"md")&" Days") -> 3 Year, 10 Month, 20 Days | AE5: =N5+U5 -> 0 | AF5: =IF(V5>0,1,0) -> 0 | AG5: =D5&E5 -> CA01 | AH5: =IF(ISNA(VLOOKUP(L5,'MASTER DATA'!$A$1:$F$192,6,0)),0,VLOOKUP(L5,'MASTER DATA'!$A$1:$F$192,6,0))*AE5 -> 0 | AI5: =VLOOKUP($D5,'warehouse mapping'!$AN$7:$AO$17,2,0) -> Aktif | AJ5: =IF(AF5=0,1,0) -> 1 | AK5: =IF(AND(AJ5=1,AI5="aktif"),D5,"") -> CA | AM5: =COUNTIF($H$5:$H$2564,H5) -> 1 | AN5: =ISNUMBER(V5) -> TRUE
A6: =H6&L6 -> CA01A02550025043 | B6: =R6+S6 -> 0 | C6: =T6+U6 -> 0 | D6: =LEFT(H6,2) -> CA | E6: =MID(H6,3,2) -> 01 | F6: =MID(H6,5,1) -> A | G6: =RIGHT(H6,2) -> 02 | H6: CA01A02 | I6: 12690046 | J6: 46254 | K6: 47703 | L6: 550025043 | M6: =IF(ISNA(VLOOKUP(L6,'MASTER DATA'!$A$1:$B$192,2,0)),"",VLOOKUP(L6,'MASTER DATA'!$A$1:$B$192,2,0)) -> Spirax S2 A 80W-90_1*209L_A227 | N6: 0 | O6: =(V6-P6)/Q6 -> 0 | P6: =MOD(V6,Q6) -> 0 | Q6: =VLOOKUP(L6,'MASTER DATA'!$A$1:$E$192,5,0) -> 4 | R6: =SUMIF('picking of the day'!$H$4:$H$358,WMS!H6&WMS!L6,'picking of the day'!$E$4:$E$358) -> 0 | U6: =IF(ISNA(VLOOKUP(H6,'data putaway'!$A$1:$E$530,3,0)),0,VLOOKUP(H6,'data putaway'!$A$1:$E$530,3,0)) -> 0 | V6: =(N6+T6+U6)-(R6+S6) -> 0 | W6: =IF(ISNA(VLOOKUP(H6,'data putaway'!$A$1:$E$530,2,0)),0,VLOOKUP(H6,'data putaway'!$A$1:$E$530,2,0)) -> 0 | X6: =W6=L6 -> FALSE | Y6: =IF(ISNA(VLOOKUP(H6,'data putaway'!$A$1:$E$530,4,0)),0,VLOOKUP(H6,'data putaway'!$A$1:$E$530,4,0)) -> 0 | Z6: =IF(ISNA(VLOOKUP(H6,'data putaway'!$A$1:$E$530,5,0)),0,VLOOKUP(H6,'data putaway'!$A$1:$E$530,5,0)) -> 0 | AA6: =Y6=I6 -> FALSE | AB6: =Z6=K6 -> FALSE | AC6: =IF(J6="","",DATEDIF(J6,NOW(),"ym")&" Month"&", "&DATEDIF(J6,NOW(),"md")&" Days") -> 0 Month, 29 Days | AD6: =IF(K6="","",DATEDIF(NOW(),K6,"y")&" Year"&", "&DATEDIF(NOW(),K6,"ym")&" Month"&", "&DATEDIF(NOW(),K6,"md")&" Days") -> 3 Year, 10 Month, 21 Days | AE6: =N6+U6 -> 0 | AF6: =IF(V6>0,1,0) -> 0 | AG6: =D6&E6 -> CA01 | AH6: =IF(ISNA(VLOOKUP(L6,'MASTER DATA'!$A$1:$F$192,6,0)),0,VLOOKUP(L6,'MASTER DATA'!$A$1:$F$192,6,0))*AE6 -> 0 | AI6: =VLOOKUP($D6,'warehouse mapping'!$AN$7:$AO$17,2,0) -> Aktif | AJ6: =IF(AF6=0,1,0) -> 1 | AK6: =IF(AND(AJ6=1,AI6="aktif"),D6,"") -> CA | AM6: =COUNTIF($H$5:$H$2564,H6) -> 1 | AN6: =ISNUMBER(V6) -> TRUE
A7: =H7&L7 -> CA01B01550027259 | B7: =R7+S7 -> 0 | C7: =T7+U7 -> 0 | D7: =LEFT(H7,2) -> CA | E7: =MID(H7,3,2) -> 01 | F7: =MID(H7,5,1) -> B | G7: =RIGHT(H7,2) -> 01 | H7: CA01B01 | I7: 12675312 | J7: 46254 | K7: 47689 | L7: 550027259 | M7: =IF(ISNA(VLOOKUP(L7,'MASTER DATA'!$A$1:$B$192,2,0)),"",VLOOKUP(L7,'MASTER DATA'!$A$1:$B$192,2,0)) -> Gadus S2 V220 2_1*770kg_A227 | N7: 1 | O7: =(V7-P7)/Q7 -> 1 | P7: =MOD(V7,Q7) -> 0 | Q7: =VLOOKUP(L7,'MASTER DATA'!$A$1:$E$192,5,0) -> 1 | R7: =SUMIF('picking of the day'!$H$4:$H$358,WMS!H7&WMS!L7,'picking of the day'!$E$4:$E$358) -> 0 | U7: =IF(ISNA(VLOOKUP(H7,'data putaway'!$A$1:$E$530,3,0)),0,VLOOKUP(H7,'data putaway'!$A$1:$E$530,3,0)) -> 0 | V7: =(N7+T7+U7)-(R7+S7) -> 1 | W7: =IF(ISNA(VLOOKUP(H7,'data putaway'!$A$1:$E$530,2,0)),0,VLOOKUP(H7,'data putaway'!$A$1:$E$530,2,0)) -> 0 | X7: =W7=L7 -> FALSE | Y7: =IF(ISNA(VLOOKUP(H7,'data putaway'!$A$1:$E$530,4,0)),0,VLOOKUP(H7,'data putaway'!$A$1:$E$530,4,0)) -> 0 | Z7: =IF(ISNA(VLOOKUP(H7,'data putaway'!$A$1:$E$530,5,0)),0,VLOOKUP(H7,'data putaway'!$A$1:$E$530,5,0)) -> 0 | AA7: =Y7=I7 -> FALSE | AB7: =Z7=K7 -> FALSE | AC7: =IF(J7="","",DATEDIF(J7,NOW(),"ym")&" Month"&", "&DATEDIF(J7,NOW(),"md")&" Days") -> 0 Month, 29 Days | AD7: =IF(K7="","",DATEDIF(NOW(),K7,"y")&" Year"&", "&DATEDIF(NOW(),K7,"ym")&" Month"&", "&DATEDIF(NOW(),K7,"md")&" Days") -> 3 Year, 10 Month, 7 Days | AE7: =N7+U7 -> 1 | AF7: =IF(V7>0,1,0) -> 1 | AG7: =D7&E7 -> CA01 | AH7: =IF(ISNA(VLOOKUP(L7,'MASTER DATA'!$A$1:$F$192,6,0)),0,VLOOKUP(L7,'MASTER DATA'!$A$1:$F$192,6,0))*AE7 -> 770 | AI7: =VLOOKUP($D7,'warehouse mapping'!$AN$7:$AO$17,2,0) -> Aktif | AJ7: =IF(AF7=0,1,0) -> 0 | AK7: =IF(AND(AJ7=1,AI7="aktif"),D7,"") | AM7: =COUNTIF($H$5:$H$2564,H7) -> 1 | AN7: =ISNUMBER(V7) -> TRUE
A8: =H8&L8 -> CA01B02550027259 | B8: =R8+S8 -> 0 | C8: =T8+U8 -> 0 | D8: =LEFT(H8,2) -> CA | E8: =MID(H8,3,2) -> 01 | F8: =MID(H8,5,1) -> B | G8: =RIGHT(H8,2) -> 02 | H8: CA01B02 | I8: 12675312 | J8: 46254 | K8: 47689 | L8: 550027259 | M8: =IF(ISNA(VLOOKUP(L8,'MASTER DATA'!$A$1:$B$192,2,0)),"",VLOOKUP(L8,'MASTER DATA'!$A$1:$B$192,2,0)) -> Gadus S2 V220 2_1*770kg_A227 | N8: 1 | O8: =(V8-P8)/Q8 -> 1 | P8: =MOD(V8,Q8) -> 0 | Q8: =VLOOKUP(L8,'MASTER DATA'!$A$1:$E$192,5,0) -> 1 | R8: =SUMIF('picking of the day'!$H$4:$H$358,WMS!H8&WMS!L8,'picking of the day'!$E$4:$E$358) -> 0 | U8: =IF(ISNA(VLOOKUP(H8,'data putaway'!$A$1:$E$530,3,0)),0,VLOOKUP(H8,'data putaway'!$A$1:$E$530,3,0)) -> 0 | V8: =(N8+T8+U8)-(R8+S8) -> 1 | W8: =IF(ISNA(VLOOKUP(H8,'data putaway'!$A$1:$E$530,2,0)),0,VLOOKUP(H8,'data putaway'!$A$1:$E$530,2,0)) -> 0 | X8: =W8=L8 -> FALSE | Y8: =IF(ISNA(VLOOKUP(H8,'data putaway'!$A$1:$E$530,4,0)),0,VLOOKUP(H8,'data putaway'!$A$1:$E$530,4,0)) -> 0 | Z8: =IF(ISNA(VLOOKUP(H8,'data putaway'!$A$1:$E$530,5,0)),0,VLOOKUP(H8,'data putaway'!$A$1:$E$530,5,0)) -> 0 | AA8: =Y8=I8 -> FALSE | AB8: =Z8=K8 -> FALSE | AC8: =IF(J8="","",DATEDIF(J8,NOW(),"ym")&" Month"&", "&DATEDIF(J8,NOW(),"md")&" Days") -> 0 Month, 29 Days | AD8: =IF(K8="","",DATEDIF(NOW(),K8,"y")&" Year"&", "&DATEDIF(NOW(),K8,"ym")&" Month"&", "&DATEDIF(NOW(),K8,"md")&" Days") -> 3 Year, 10 Month, 7 Days | AE8: =N8+U8 -> 1 | AF8: =IF(V8>0,1,0) -> 1 | AG8: =D8&E8 -> CA01 | AH8: =IF(ISNA(VLOOKUP(L8,'MASTER DATA'!$A$1:$F$192,6,0)),0,VLOOKUP(L8,'MASTER DATA'!$A$1:$F$192,6,0))*AE8 -> 770 | AI8: =VLOOKUP($D8,'warehouse mapping'!$AN$7:$AO$17,2,0) -> Aktif | AJ8: =IF(AF8=0,1,0) -> 0 | AK8: =IF(AND(AJ8=1,AI8="aktif"),D8,"") | AM8: =COUNTIF($H$5:$H$2564,H8) -> 1 | AN8: =ISNUMBER(V8) -> TRUE
A9: =H9&L9 -> CA01C01550070612 | B9: =R9+S9 -> 0 | C9: =T9+U9 -> 0 | D9: =LEFT(H9,2) -> CA | E9: =MID(H9,3,2) -> 01 | F9: =MID(H9,5,1) -> C | G9: =RIGHT(H9,2) -> 01 | H9: CA01C01 | I9: 19H26JJ | J9: 46263 | K9: 47714 | L9: 550070612 | M9: =IF(ISNA(VLOOKUP(L9,'MASTER DATA'!$A$1:$B$192,2,0)),"",VLOOKUP(L9,'MASTER DATA'!$A$1:$B$192,2,0)) -> HlxHX610W40SP_12*1L_A04W | N9: 44 | O9: =(V9-P9)/Q9 -> 1 | P9: =MOD(V9,Q9) -> 0 | Q9: =VLOOKUP(L9,'MASTER DATA'!$A$1:$E$192,5,0) -> 44 | R9: =SUMIF('picking of the day'!$H$4:$H$358,WMS!H9&WMS!L9,'picking of the day'!$E$4:$E$358) -> 0 | U9: =IF(ISNA(VLOOKUP(H9,'data putaway'!$A$1:$E$530,3,0)),0,VLOOKUP(H9,'data putaway'!$A$1:$E$530,3,0)) -> 0 | V9: =(N9+T9+U9)-(R9+S9) -> 44 | W9: =IF(ISNA(VLOOKUP(H9,'data putaway'!$A$1:$E$530,2,0)),0,VLOOKUP(H9,'data putaway'!$A$1:$E$530,2,0)) -> 0 | X9: =W9=L9 -> FALSE | Y9: =IF(ISNA(VLOOKUP(H9,'data putaway'!$A$1:$E$530,4,0)),0,VLOOKUP(H9,'data putaway'!$A$1:$E$530,4,0)) -> 0 | Z9: =IF(ISNA(VLOOKUP(H9,'data putaway'!$A$1:$E$530,5,0)),0,VLOOKUP(H9,'data putaway'!$A$1:$E$530,5,0)) -> 0 | AA9: =Y9=I9 -> FALSE | AB9: =Z9=K9 -> FALSE | AC9: =IF(J9="","",DATEDIF(J9,NOW(),"ym")&" Month"&", "&DATEDIF(J9,NOW(),"md")&" Days") -> 0 Month, 20 Days | AD9: =IF(K9="","",DATEDIF(NOW(),K9,"y")&" Year"&", "&DATEDIF(NOW(),K9,"ym")&" Month"&", "&DATEDIF(NOW(),K9,"md")&" Days") -> 3 Year, 11 Month, 1 Days | AE9: =N9+U9 -> 44 | AF9: =IF(V9>0,1,0) -> 1 | AG9: =D9&E9 -> CA01 | AH9: =IF(ISNA(VLOOKUP(L9,'MASTER DATA'!$A$1:$F$192,6,0)),0,VLOOKUP(L9,'MASTER DATA'!$A$1:$F$192,6,0))*AE9 -> 528 | AI9: =VLOOKUP($D9,'warehouse mapping'!$AN$7:$AO$17,2,0) -> Aktif | AJ9: =IF(AF9=0,1,0) -> 0 | AK9: =IF(AND(AJ9=1,AI9="aktif"),D9,"") | AM9: =COUNTIF($H$5:$H$2564,H9) -> 1 | AN9: =ISNUMBER(V9) -> TRUE
A10: =H10&L10 -> CA01C02550054596 | B10: =R10+S10 -> 0 | C10: =T10+U10 -> 0 | D10: =LEFT(H10,2) -> CA | E10: =MID(H10,3,2) -> 01 | F10: =MID(H10,5,1) -> C | G10: =RIGHT(H10,2) -> 02 | H10: CA01C02 | I10: 12663919 | J10: 46233 | K10: 47638 | L10: 550054596 | M10: =IF(ISNA(VLOOKUP(L10,'MASTER DATA'!$A$1:$B$192,2,0)),"",VLOOKUP(L10,'MASTER DATA'!$A$1:$B$192,2,0)) -> HinoGEO15W40CI4DH1_1*200L_A04W | N10: 0 | O10: =(V10-P10)/Q10 -> 0 | P10: =MOD(V10,Q10) -> 0 | Q10: =VLOOKUP(L10,'MASTER DATA'!$A$1:$E$192,5,0) -> 4 | R10: =SUMIF('picking of the day'!$H$4:$H$358,WMS!H10&WMS!L10,'picking of the day'!$E$4:$E$358) -> 0 | U10: =IF(ISNA(VLOOKUP(H10,'data putaway'!$A$1:$E$530,3,0)),0,VLOOKUP(H10,'data putaway'!$A$1:$E$530,3,0)) -> 0 | V10: =(N10+T10+U10)-(R10+S10) -> 0 | W10: =IF(ISNA(VLOOKUP(H10,'data putaway'!$A$1:$E$530,2,0)),0,VLOOKUP(H10,'data putaway'!$A$1:$E$530,2,0)) -> 0 | X10: =W10=L10 -> FALSE | Y10: =IF(ISNA(VLOOKUP(H10,'data putaway'!$A$1:$E$530,4,0)),0,VLOOKUP(H10,'data putaway'!$A$1:$E$530,4,0)) -> 0 | Z10: =IF(ISNA(VLOOKUP(H10,'data putaway'!$A$1:$E$530,5,0)),0,VLOOKUP(H10,'data putaway'!$A$1:$E$530,5,0)) -> 0 | AA10: =Y10=I10 -> FALSE | AB10: =Z10=K10 -> FALSE | AC10: =IF(J10="","",DATEDIF(J10,NOW(),"ym")&" Month"&", "&DATEDIF(J10,NOW(),"md")&" Days") -> 1 Month, 19 Days | AD10: =IF(K10="","",DATEDIF(NOW(),K10,"y")&" Year"&", "&DATEDIF(NOW(),K10,"ym")&" Month"&", "&DATEDIF(NOW(),K10,"md")&" Days") -> 3 Year, 8 Month, 17 Days | AE10: =N10+U10 -> 0 | AF10: =IF(V10>0,1,0) -> 0 | AG10: =D10&E10 -> CA01 | AH10: =IF(ISNA(VLOOKUP(L10,'MASTER DATA'!$A$1:$F$192,6,0)),0,VLOOKUP(L10,'MASTER DATA'!$A$1:$F$192,6,0))*AE10 -> 0 | AI10: =VLOOKUP($D10,'warehouse mapping'!$AN$7:$AO$17,2,0) -> Aktif | AJ10: =IF(AF10=0,1,0) -> 1 | AK10: =IF(AND(AJ10=1,AI10="aktif"),D10,"") -> CA | AM10: =COUNTIF($H$5:$H$2564,H10) -> 1 | AN10: =ISNUMBER(V10) -> TRUE
A11: =H11&L11 -> CA01D01550062464 | B11: =R11+S11 -> 0 | C11: =T11+U11 -> 0 | D11: =LEFT(H11,2) -> CA | E11: =MID(H11,3,2) -> 01 | F11: =MID(H11,5,1) -> D | G11: =RIGHT(H11,2) -> 01 | H11: CA01D01 | I11: 17H26JJ | J11: 46261 | K11: 47712 | L11: 550062464 | M11: =IF(ISNA(VLOOKUP(L11,'MASTER DATA'!$A$1:$B$192,2,0)),"",VLOOKUP(L11,'MASTER DATA'!$A$1:$B$192,2,0)) -> Adv4TAX7Sc10W30SNMB_12*0.8L_A04W | N11: 48 | O11: =(V11-P11)/Q11 -> 1 | P11: =MOD(V11,Q11) -> 0 | Q11: =VLOOKUP(L11,'MASTER DATA'!$A$1:$E$192,5,0) -> 48 | R11: =SUMIF('picking of the day'!$H$4:$H$358,WMS!H11&WMS!L11,'picking of the day'!$E$4:$E$358) -> 0 | U11: =IF(ISNA(VLOOKUP(H11,'data putaway'!$A$1:$E$530,3,0)),0,VLOOKUP(H11,'data putaway'!$A$1:$E$530,3,0)) -> 0 | V11: =(N11+T11+U11)-(R11+S11) -> 48 | W11: =IF(ISNA(VLOOKUP(H11,'data putaway'!$A$1:$E$530,2,0)),0,VLOOKUP(H11,'data putaway'!$A$1:$E$530,2,0)) -> 0 | X11: =W11=L11 -> FALSE | Y11: =IF(ISNA(VLOOKUP(H11,'data putaway'!$A$1:$E$530,4,0)),0,VLOOKUP(H11,'data putaway'!$A$1:$E$530,4,0)) -> 0 | Z11: =IF(ISNA(VLOOKUP(H11,'data putaway'!$A$1:$E$530,5,0)),0,VLOOKUP(H11,'data putaway'!$A$1:$E$530,5,0)) -> 0 | AA11: =Y11=I11 -> FALSE | AB11: =Z11=K11 -> FALSE | AC11: =IF(J11="","",DATEDIF(J11,NOW(),"ym")&" Month"&", "&DATEDIF(J11,NOW(),"md")&" Days") -> 0 Month, 22 Days | AD11: =IF(K11="","",DATEDIF(NOW(),K11,"y")&" Year"&", "&DATEDIF(NOW(),K11,"ym")&" Month"&", "&DATEDIF(NOW(),K11,"md")&" Days") -> 3 Year, 10 Month, 30 Days | AE11: =N11+U11 -> 48 | AF11: =IF(V11>0,1,0) -> 1 | AG11: =D11&E11 -> CA01 | AH11: =IF(ISNA(VLOOKUP(L11,'MASTER DATA'!$A$1:$F$192,6,0)),0,VLOOKUP(L11,'MASTER DATA'!$A$1:$F$192,6,0))*AE11 -> 460.8 | AI11: =VLOOKUP($D11,'warehouse mapping'!$AN$7:$AO$17,2,0) -> Aktif | AJ11: =IF(AF11=0,1,0) -> 0 | AK11: =IF(AND(AJ11=1,AI11="aktif"),D11,"") | AM11: =COUNTIF($H$5:$H$2564,H11) -> 1 | AN11: =ISNUMBER(V11) -> TRUE
A12: =H12&L12 -> CA01D02550062464 | B12: =R12+S12 -> 0 | C12: =T12+U12 -> 0 | D12: =LEFT(H12,2) -> CA | E12: =MID(H12,3,2) -> 01 | F12: =MID(H12,5,1) -> D | G12: =RIGHT(H12,2) -> 02 | H12: CA01D02 | I12: 17H26JJ | J12: 46261 | K12: 47712 | L12: 550062464 | M12: =IF(ISNA(VLOOKUP(L12,'MASTER DATA'!$A$1:$B$192,2,0)),"",VLOOKUP(L12,'MASTER DATA'!$A$1:$B$192,2,0)) -> Adv4TAX7Sc10W30SNMB_12*0.8L_A04W | N12: 48 | O12: =(V12-P12)/Q12 -> 1 | P12: =MOD(V12,Q12) -> 0 | Q12: =VLOOKUP(L12,'MASTER DATA'!$A$1:$E$192,5,0) -> 48 | R12: =SUMIF('picking of the day'!$H$4:$H$358,WMS!H12&WMS!L12,'picking of the day'!$E$4:$E$358) -> 0 | U12: =IF(ISNA(VLOOKUP(H12,'data putaway'!$A$1:$E$530,3,0)),0,VLOOKUP(H12,'data putaway'!$A$1:$E$530,3,0)) -> 0 | V12: =(N12+T12+U12)-(R12+S12) -> 48 | W12: =IF(ISNA(VLOOKUP(H12,'data putaway'!$A$1:$E$530,2,0)),0,VLOOKUP(H12,'data putaway'!$A$1:$E$530,2,0)) -> 0 | X12: =W12=L12 -> FALSE | Y12: =IF(ISNA(VLOOKUP(H12,'data putaway'!$A$1:$E$530,4,0)),0,VLOOKUP(H12,'data putaway'!$A$1:$E$530,4,0)) -> 0 | Z12: =IF(ISNA(VLOOKUP(H12,'data putaway'!$A$1:$E$530,5,0)),0,VLOOKUP(H12,'data putaway'!$A$1:$E$530,5,0)) -> 0 | AA12: =Y12=I12 -> FALSE | AB12: =Z12=K12 -> FALSE | AC12: =IF(J12="","",DATEDIF(J12,NOW(),"ym")&" Month"&", "&DATEDIF(J12,NOW(),"md")&" Days") -> 0 Month, 22 Days | AD12: =IF(K12="","",DATEDIF(NOW(),K12,"y")&" Year"&", "&DATEDIF(NOW(),K12,"ym")&" Month"&", "&DATEDIF(NOW(),K12,"md")&" Days") -> 3 Year, 10 Month, 30 Days | AE12: =N12+U12 -> 48 | AF12: =IF(V12>0,1,0) -> 1 | AG12: =D12&E12 -> CA01 | AH12: =IF(ISNA(VLOOKUP(L12,'MASTER DATA'!$A$1:$F$192,6,0)),0,VLOOKUP(L12,'MASTER DATA'!$A$1:$F$192,6,0))*AE12 -> 460.8 | AI12: =VLOOKUP($D12,'warehouse mapping'!$AN$7:$AO$17,2,0) -> Aktif | AJ12: =IF(AF12=0,1,0) -> 0 | AK12: =IF(AND(AJ12=1,AI12="aktif"),D12,"") | AM12: =COUNTIF($H$5:$H$2564,H12) -> 1 | AN12: =ISNUMBER(V12) -> TRUE
A13: =H13&L13 -> CA01E01550062464 | B13: =R13+S13 -> 0 | C13: =T13+U13 -> 0 | D13: =LEFT(H13,2) -> CA | E13: =MID(H13,3,2) -> 01 | F13: =MID(H13,5,1) -> E | G13: =RIGHT(H13,2) -> 01 | H13: CA01E01 | I13: 17H26JJ | J13: 46261 | K13: 47712 | L13: 550062464 | M13: =IF(ISNA(VLOOKUP(L13,'MASTER DATA'!$A$1:$B$192,2,0)),"",VLOOKUP(L13,'MASTER DATA'!$A$1:$B$192,2,0)) -> Adv4TAX7Sc10W30SNMB_12*0.8L_A04W | N13: 48 | O13: =(V13-P13)/Q13 -> 1 | P13: =MOD(V13,Q13) -> 0 | Q13: =VLOOKUP(L13,'MASTER DATA'!$A$1:$E$192,5,0) -> 48 | R13: =SUMIF('picking of the day'!$H$4:$H$358,WMS!H13&WMS!L13,'picking of the day'!$E$4:$E$358) -> 0 | U13: =IF(ISNA(VLOOKUP(H13,'data putaway'!$A$1:$E$530,3,0)),0,VLOOKUP(H13,'data putaway'!$A$1:$E$530,3,0)) -> 0 | V13: =(N13+T13+U13)-(R13+S13) -> 48 | W13: =IF(ISNA(VLOOKUP(H13,'data putaway'!$A$1:$E$530,2,0)),0,VLOOKUP(H13,'data putaway'!$A$1:$E$530,2,0)) -> 0 | X13: =W13=L13 -> FALSE | Y13: =IF(ISNA(VLOOKUP(H13,'data putaway'!$A$1:$E$530,4,0)),0,VLOOKUP(H13,'data putaway'!$A$1:$E$530,4,0)) -> 0 | Z13: =IF(ISNA(VLOOKUP(H13,'data putaway'!$A$1:$E$530,5,0)),0,VLOOKUP(H13,'data putaway'!$A$1:$E$530,5,0)) -> 0 | AA13: =Y13=I13 -> FALSE | AB13: =Z13=K13 -> FALSE | AC13: =IF(J13="","",DATEDIF(J13,NOW(),"ym")&" Month"&", "&DATEDIF(J13,NOW(),"md")&" Days") -> 0 Month, 22 Days | AD13: =IF(K13="","",DATEDIF(NOW(),K13,"y")&" Year"&", "&DATEDIF(NOW(),K13,"ym")&" Month"&", "&DATEDIF(NOW(),K13,"md")&" Days") -> 3 Year, 10 Month, 30 Days | AE13: =N13+U13 -> 48 | AF13: =IF(V13>0,1,0) -> 1 | AG13: =D13&E13 -> CA01 | AH13: =IF(ISNA(VLOOKUP(L13,'MASTER DATA'!$A$1:$F$192,6,0)),0,VLOOKUP(L13,'MASTER DATA'!$A$1:$F$192,6,0))*AE13 -> 460.8 | AI13: =VLOOKUP($D13,'warehouse mapping'!$AN$7:$AO$17,2,0) -> Aktif | AJ13: =IF(AF13=0,1,0) -> 0 | AK13: =IF(AND(AJ13=1,AI13="aktif"),D13,"") | AM13: =COUNTIF($H$5:$H$2564,H13) -> 1 | AN13: =ISNUMBER(V13) -> TRUE
A14: =H14&L14 -> CA01E02550062464 | B14: =R14+S14 -> 0 | C14: =T14+U14 -> 0 | D14: =LEFT(H14,2) -> CA | E14: =MID(H14,3,2) -> 01 | F14: =MID(H14,5,1) -> E | G14: =RIGHT(H14,2) -> 02 | H14: CA01E02 | I14: 17H26JJ | J14: 46261 | K14: 47712 | L14: 550062464 | M14: =IF(ISNA(VLOOKUP(L14,'MASTER DATA'!$A$1:$B$192,2,0)),"",VLOOKUP(L14,'MASTER DATA'!$A$1:$B$192,2,0)) -> Adv4TAX7Sc10W30SNMB_12*0.8L_A04W | N14: 48 | O14: =(V14-P14)/Q14 -> 1 | P14: =MOD(V14,Q14) -> 0 | Q14: =VLOOKUP(L14,'MASTER DATA'!$A$1:$E$192,5,0) -> 48 | R14: =SUMIF('picking of the day'!$H$4:$H$358,WMS!H14&WMS!L14,'picking of the day'!$E$4:$E$358) -> 0 | U14: =IF(ISNA(VLOOKUP(H14,'data putaway'!$A$1:$E$530,3,0)),0,VLOOKUP(H14,'data putaway'!$A$1:$E$530,3,0)) -> 0 | V14: =(N14+T14+U14)-(R14+S14) -> 48 | W14: =IF(ISNA(VLOOKUP(H14,'data putaway'!$A$1:$E$530,2,0)),0,VLOOKUP(H14,'data putaway'!$A$1:$E$530,2,0)) -> 0 | X14: =W14=L14 -> FALSE | Y14: =IF(ISNA(VLOOKUP(H14,'data putaway'!$A$1:$E$530,4,0)),0,VLOOKUP(H14,'data putaway'!$A$1:$E$530,4,0)) -> 0 | Z14: =IF(ISNA(VLOOKUP(H14,'data putaway'!$A$1:$E$530,5,0)),0,VLOOKUP(H14,'data putaway'!$A$1:$E$530,5,0)) -> 0 | AA14: =Y14=I14 -> FALSE | AB14: =Z14=K14 -> FALSE | AC14: =IF(J14="","",DATEDIF(J14,NOW(),"ym")&" Month"&", "&DATEDIF(J14,NOW(),"md")&" Days") -> 0 Month, 22 Days | AD14: =IF(K14="","",DATEDIF(NOW(),K14,"y")&" Year"&", "&DATEDIF(NOW(),K14,"ym")&" Month"&", "&DATEDIF(NOW(),K14,"md")&" Days") -> 3 Year, 10 Month, 30 Days | AE14: =N14+U14 -> 48 | AF14: =IF(V14>0,1,0) -> 1 | AG14: =D14&E14 -> CA01 | AH14: =IF(ISNA(VLOOKUP(L14,'MASTER DATA'!$A$1:$F$192,6,0)),0,VLOOKUP(L14,'MASTER DATA'!$A$1:$F$192,6,0))*AE14 -> 460.8 | AI14: =VLOOKUP($D14,'warehouse mapping'!$AN$7:$AO$17,2,0) -> Aktif | AJ14: =IF(AF14=0,1,0) -> 0 | AK14: =IF(AND(AJ14=1,AI14="aktif"),D14,"") | AM14: =COUNTIF($H$5:$H$2564,H14) -> 1 | AN14: =ISNUMBER(V14) -> TRUE
A15: =H15&L15 -> CA02A01550062285 | B15: =R15+S15 -> 0 | C15: =T15+U15 -> 0 | D15: =LEFT(H15,2) -> CA | E15: =MID(H15,3,2) -> 02 | F15: =MID(H15,5,1) -> A | G15: =RIGHT(H15,2) -> 01 | H15: CA02A01 | I15: 12626159 | J15: 46122 | K15: 47563 | L15: 550062285 | M15: =IF(ISNA(VLOOKUP(L15,'MASTER DATA'!$A$1:$B$192,2,0)),"",VLOOKUP(L15,'MASTER DATA'!$A$1:$B$192,2,0)) -> Gadus S3 V460DM 2_1*770kg_A227 | N15: 1 | O15: =(V15-P15)/Q15 -> 1 | P15: =MOD(V15,Q15) -> 0 | Q15: =VLOOKUP(L15,'MASTER DATA'!$A$1:$E$192,5,0) -> 1 | R15: =SUMIF('picking of the day'!$H$4:$H$358,WMS!H15&WMS!L15,'picking of the day'!$E$4:$E$358) -> 0 | U15: =IF(ISNA(VLOOKUP(H15,'data putaway'!$A$1:$E$530,3,0)),0,VLOOKUP(H15,'data putaway'!$A$1:$E$530,3,0)) -> 0 | V15: =(N15+T15+U15)-(R15+S15) -> 1 | W15: =IF(ISNA(VLOOKUP(H15,'data putaway'!$A$1:$E$530,2,0)),0,VLOOKUP(H15,'data putaway'!$A$1:$E$530,2,0)) -> 0 | X15: =W15=L15 -> FALSE | Y15: =IF(ISNA(VLOOKUP(H15,'data putaway'!$A$1:$E$530,4,0)),0,VLOOKUP(H15,'data putaway'!$A$1:$E$530,4,0)) -> 0 | Z15: =IF(ISNA(VLOOKUP(H15,'data putaway'!$A$1:$E$530,5,0)),0,VLOOKUP(H15,'data putaway'!$A$1:$E$530,5,0)) -> 0 | AA15: =Y15=I15 -> FALSE | AB15: =Z15=K15 -> FALSE | AC15: =IF(J15="","",DATEDIF(J15,NOW(),"ym")&" Month"&", "&DATEDIF(J15,NOW(),"md")&" Days") -> 5 Month, 8 Days | AD15: =IF(K15="","",DATEDIF(NOW(),K15,"y")&" Year"&", "&DATEDIF(NOW(),K15,"ym")&" Month"&", "&DATEDIF(NOW(),K15,"md")&" Days") -> 3 Year, 6 Month, 3 Days | AE15: =N15+U15 -> 1 | AF15: =IF(V15>0,1,0) -> 1 | AG15: =D15&E15 -> CA02 | AH15: =IF(ISNA(VLOOKUP(L15,'MASTER DATA'!$A$1:$F$192,6,0)),0,VLOOKUP(L15,'MASTER DATA'!$A$1:$F$192,6,0))*AE15 -> 770 | AI15: =VLOOKUP($D15,'warehouse mapping'!$AN$7:$AO$17,2,0) -> Aktif | AJ15: =IF(AF15=0,1,0) -> 0 | AK15: =IF(AND(AJ15=1,AI15="aktif"),D15,"") | AL15: Fluidbag | AM15: =COUNTIF($H$5:$H$2564,H15) -> 1 | AN15: =ISNUMBER(V15) -> TRUE
A16: =H16&L16 -> CA02A02550062285 | B16: =R16+S16 -> 0 | C16: =T16+U16 -> 0 | D16: =LEFT(H16,2) -> CA | E16: =MID(H16,3,2) -> 02 | F16: =MID(H16,5,1) -> A | G16: =RIGHT(H16,2) -> 02 | H16: CA02A02 | I16: 12626159 | J16: 46122 | K16: 47563 | L16: 550062285 | M16: =IF(ISNA(VLOOKUP(L16,'MASTER DATA'!$A$1:$B$192,2,0)),"",VLOOKUP(L16,'MASTER DATA'!$A$1:$B$192,2,0)) -> Gadus S3 V460DM 2_1*770kg_A227 | N16: 1 | O16: =(V16-P16)/Q16 -> 1 | P16: =MOD(V16,Q16) -> 0 | Q16: =VLOOKUP(L16,'MASTER DATA'!$A$1:$E$192,5,0) -> 1 | R16: =SUMIF('picking of the day'!$H$4:$H$358,WMS!H16&WMS!L16,'picking of the day'!$E$4:$E$358) -> 0 | U16: =IF(ISNA(VLOOKUP(H16,'data putaway'!$A$1:$E$530,3,0)),0,VLOOKUP(H16,'data putaway'!$A$1:$E$530,3,0)) -> 0 | V16: =(N16+T16+U16)-(R16+S16) -> 1 | W16: =IF(ISNA(VLOOKUP(H16,'data putaway'!$A$1:$E$530,2,0)),0,VLOOKUP(H16,'data putaway'!$A$1:$E$530,2,0)) -> 0 | X16: =W16=L16 -> FALSE | Y16: =IF(ISNA(VLOOKUP(H16,'data putaway'!$A$1:$E$530,4,0)),0,VLOOKUP(H16,'data putaway'!$A$1:$E$530,4,0)) -> 0 | Z16: =IF(ISNA(VLOOKUP(H16,'data putaway'!$A$1:$E$530,5,0)),0,VLOOKUP(H16,'data putaway'!$A$1:$E$530,5,0)) -> 0 | AA16: =Y16=I16 -> FALSE | AB16: =Z16=K16 -> FALSE | AC16: =IF(J16="","",DATEDIF(J16,NOW(),"ym")&" Month"&", "&DATEDIF(J16,NOW(),"md")&" Days") -> 5 Month, 8 Days | AD16: =IF(K16="","",DATEDIF(NOW(),K16,"y")&" Year"&", "&DATEDIF(NOW(),K16,"ym")&" Month"&", "&DATEDIF(NOW(),K16,"md")&" Days") -> 3 Year, 6 Month, 3 Days | AE16: =N16+U16 -> 1 | AF16: =IF(V16>0,1,0) -> 1 | AG16: =D16&E16 -> CA02 | AH16: =IF(ISNA(VLOOKUP(L16,'MASTER DATA'!$A$1:$F$192,6,0)),0,VLOOKUP(L16,'MASTER DATA'!$A$1:$F$192,6,0))*AE16 -> 770 | AI16: =VLOOKUP($D16,'warehouse mapping'!$AN$7:$AO$17,2,0) -> Aktif | AJ16: =IF(AF16=0,1,0) -> 0 | AK16: =IF(AND(AJ16=1,AI16="aktif"),D16,"") | AL16: Fluidbag | AM16: =COUNTIF($H$5:$H$2564,H16) -> 1 | AN16: =ISNUMBER(V16) -> TRUE
